<?xml version="1.0"?>

<robot name="wheel" xmlns:xacro="http://ros.org/wiki/xacro">
  <!-- patrick_0803 define a wheel -->
  <xacro:macro name="wheel" params="parent lr offset_x offset_y offset_z width radius">
    <!-- joint -->
    <joint name="wheel_${lr}_joint" type="continuous">
      <parent link="${parent}_link"/>
      <child link="wheel_${lr}_link"/>
      <origin xyz="${offset_x} ${offset_y} ${offset_z}" 
              rpy="${-PI/2} 0 0"/>
      <axis xyz="0 0 1"/>
<!--      <limit lower="-100000.0"
             upper="100000.0"
             effort="5.0"
             velocity="1.0"/>
      <safety_controller k_position="1"
                         k_velocity="1"
                         soft_lower_limit="-9000.0"
                         soft_upper_limit="9000.0" /> -->
    </joint>
    <!-- link -->
    <link name="wheel_${lr}_link">
      <visual>
        <geometry>
          <cylinder length="${width}" radius="${radius}"/>
        </geometry>
        <xacro:insert_block name="material_orange"/>
        <origin xyz="0 0 0" rpy="0 0 0"/>
      </visual>
      <collision>
        <geometry>
          <cylinder length="${width}" radius="${radius}"/>
        </geometry>
        <origin xyz="0 0 0" rpy="0 0 0"/>
      </collision>
      <inertial>
        <origin xyz="0 0 0" />
        <mass value="0.01" />
        <inertia ixx="0.01" ixy="0.0" ixz="0.0"
                 iyy="0.01" iyz="0.0"
                 izz="0.01" />
      </inertial>
    </link>
    <!-- gazebo parameters -->
	  <gazebo reference="wheel_${lr}_link">
	    <mu1>1.0</mu1>
	    <mu2>1.0</mu2>
      <kp>10000000.0</kp>
	    <kd>1000.0</kd>
	    <minDepth>0.001</minDepth>
	    <maxVel>1.0</maxVel>
	    <material>Gazebo/Orange</material>
	  </gazebo>       
  </xacro:macro>
</robot>
